<?xml version="1.0" ?>
<robot name="mobile_manipulator" xmlns:xacro="http://www.ros.org/wiki/xacro">

<xacro:include filename="$(find mobile_manipulator_description)/urdf/materials.xacro" />
<xacro:include filename="$(find mobile_manipulator_description)/urdf/mobile_manipulator.trans" />
<xacro:include filename="$(find mobile_manipulator_description)/gazebo/mobile_manipulator_materials.gazebo" />
<xacro:include filename="$(find mobile_manipulator_description)/gazebo/mobile_manipulator_physics.gazebo" />
<xacro:include filename="$(find mobile_manipulator_description)/gazebo/mobile_manipulator_plugins.gazebo" />
<link name="dummy">
</link>
<link name="base_link">
  <inertial>
    <origin rpy="0 0 0" xyz="1.1880172534914988e-15 1.8117263115745358e-14 0.3472850110892992"/>
    <mass value="398.8636735465949"/>
    <inertia ixx="27.323391" ixy="-0.0" ixz="0.0" iyy="42.291122" iyz="0.0" izz="47.037275"/>
  </inertial>
  <visual>
    <origin rpy="0 0 0" xyz="0 0 0"/>
    <geometry>
      <mesh filename="package://mobile_manipulator_description/meshes/base_link.stl" scale="0.001 0.001 0.001"/>
    </geometry>
    <material name="silver_default"/>
  </visual>
  <collision>
    <origin rpy="0 0 0" xyz="0 0 0"/>
    <geometry>
      <mesh filename="package://mobile_manipulator_description/meshes/base_link.stl" scale="0.001 0.001 0.001"/>
    </geometry>
  </collision>
</link>

<link name="wheel_fl_1">
  <inertial>
    <origin rpy="0 0 0" xyz="-2.070565940925917e-14 0.0 1.9886869928598117e-14"/>
    <mass value="2.8760298995910287"/>
    <inertia ixx="0.009699" ixy="-0.0" ixz="0.0" iyy="0.014605" iyz="-0.0" izz="0.009699"/>
  </inertial>
  <visual>
    <origin rpy="0 0 0" xyz="-0.35 -0.35 -0.1"/>
    <geometry>
      <mesh filename="package://mobile_manipulator_description/meshes/wheel_fl_1.stl" scale="0.001 0.001 0.001"/>
    </geometry>
    <material name="silver_default"/>
  </visual>
  <collision>
    <origin rpy="0 0 0" xyz="-0.35 -0.35 -0.1"/>
    <geometry>
      <mesh filename="package://mobile_manipulator_description/meshes/wheel_fl_1.stl" scale="0.001 0.001 0.001"/>
    </geometry>
  </collision>
</link>

<link name="wheel_fr_1">
  <inertial>
    <origin rpy="0 0 0" xyz="-2.070565940925917e-14 1.6653345369377348e-15 1.990074771640593e-14"/>
    <mass value="2.8760298995910287"/>
    <inertia ixx="0.009699" ixy="-0.0" ixz="0.0" iyy="0.014605" iyz="-0.0" izz="0.009699"/>
  </inertial>
  <visual>
    <origin rpy="0 0 0" xyz="-0.35 0.35 -0.1"/>
    <geometry>
      <mesh filename="package://mobile_manipulator_description/meshes/wheel_fr_1.stl" scale="0.001 0.001 0.001"/>
    </geometry>
    <material name="silver_default"/>
  </visual>
  <collision>
    <origin rpy="0 0 0" xyz="-0.35 0.35 -0.1"/>
    <geometry>
      <mesh filename="package://mobile_manipulator_description/meshes/wheel_fr_1.stl" scale="0.001 0.001 0.001"/>
    </geometry>
  </collision>
</link>

<link name="wheel_br_1">
  <inertial>
    <origin rpy="0 0 0" xyz="-2.0761170560490427e-14 1.6653345369377348e-15 1.9886869928598117e-14"/>
    <mass value="2.8760298995910287"/>
    <inertia ixx="0.009699" ixy="0.0" ixz="-0.0" iyy="0.014605" iyz="-0.0" izz="0.009699"/>
  </inertial>
  <visual>
    <origin rpy="0 0 0" xyz="0.35 0.35 -0.1"/>
    <geometry>
      <mesh filename="package://mobile_manipulator_description/meshes/wheel_br_1.stl" scale="0.001 0.001 0.001"/>
    </geometry>
    <material name="silver_default"/>
  </visual>
  <collision>
    <origin rpy="0 0 0" xyz="0.35 0.35 -0.1"/>
    <geometry>
      <mesh filename="package://mobile_manipulator_description/meshes/wheel_br_1.stl" scale="0.001 0.001 0.001"/>
    </geometry>
  </collision>
</link>

<link name="lidar_1">
  <inertial>
    <origin rpy="0 0 0" xyz="5.790023100122031e-18 2.2101892748399837e-14 0.02499999999999991"/>
    <mass value="3.082687791334983"/>
    <inertia ixx="0.002569" ixy="-0.0" ixz="0.0" iyy="0.002569" iyz="0.0" izz="0.003853"/>
  </inertial>
  <visual>
    <origin rpy="0 0 0" xyz="-0.0 -0.0 -0.675"/>
    <geometry>
      <mesh filename="package://mobile_manipulator_description/meshes/lidar_1.stl" scale="0.001 0.001 0.001"/>
    </geometry>
    <material name="silver_default"/>
  </visual>
  <collision>
    <origin rpy="0 0 0" xyz="-0.0 -0.0 -0.675"/>
    <geometry>
      <mesh filename="package://mobile_manipulator_description/meshes/lidar_1.stl" scale="0.001 0.001 0.001"/>
    </geometry>
  </collision>
</link>

<link name="arm_base_right_1">
  <inertial>
    <origin rpy="0 0 0" xyz="-1.1685831912934098e-14 0.0 0.0228217856471592"/>
    <mass value="3.7908869701372376"/>
    <inertia ixx="0.009461" ixy="0.0" ixz="0.0" iyy="0.009461" iyz="0.0" izz="0.017508"/>
  </inertial>
  <visual>
    <origin rpy="0 0 0" xyz="-0.0 0.5 -0.35"/>
    <geometry>
      <mesh filename="package://mobile_manipulator_description/meshes/arm_base_right_1.stl" scale="0.001 0.001 0.001"/>
    </geometry>
    <material name="silver_default"/>
  </visual>
  <collision>
    <origin rpy="0 0 0" xyz="-0.0 0.5 -0.35"/>
    <geometry>
      <mesh filename="package://mobile_manipulator_description/meshes/arm_base_right_1.stl" scale="0.001 0.001 0.001"/>
    </geometry>
  </collision>
</link>

<link name="arm_base_left_1">
  <inertial>
    <origin rpy="0 0 0" xyz="-1.1682031322150814e-14 -7.771561172376096e-16 0.022821785647177406"/>
    <mass value="3.7908869701372376"/>
    <inertia ixx="0.009461" ixy="0.0" ixz="0.0" iyy="0.009461" iyz="-0.0" izz="0.017508"/>
  </inertial>
  <visual>
    <origin rpy="0 0 0" xyz="0.0 -0.475 -0.35"/>
    <geometry>
      <mesh filename="package://mobile_manipulator_description/meshes/arm_base_left_1.stl" scale="0.001 0.001 0.001"/>
    </geometry>
    <material name="silver_default"/>
  </visual>
  <collision>
    <origin rpy="0 0 0" xyz="0.0 -0.475 -0.35"/>
    <geometry>
      <mesh filename="package://mobile_manipulator_description/meshes/arm_base_left_1.stl" scale="0.001 0.001 0.001"/>
    </geometry>
  </collision>
</link>

<link name="shoulder_right_1">
  <inertial>
    <origin rpy="0 0 0" xyz="0.009876831808453819 0.00024257366111479772 0.05892555620869172"/>
    <mass value="3.1247497467720398"/>
    <inertia ixx="0.014842" ixy="-2.6e-05" ixz="-0.003268" iyy="0.016057" iyz="-0.000102" izz="0.003681"/>
  </inertial>
  <visual>
    <origin rpy="0 0 0" xyz="-0.0 0.5 -0.4"/>
    <geometry>
      <mesh filename="package://mobile_manipulator_description/meshes/shoulder_right_1.stl" scale="0.001 0.001 0.001"/>
    </geometry>
    <material name="silver_default"/>
  </visual>
  <collision>
    <origin rpy="0 0 0" xyz="-0.0 0.5 -0.4"/>
    <geometry>
      <mesh filename="package://mobile_manipulator_description/meshes/shoulder_right_1.stl" scale="0.001 0.001 0.001"/>
    </geometry>
  </collision>
</link>

<link name="shoulder_left_1">
  <inertial>
    <origin rpy="0 0 0" xyz="0.009876831808453845 0.00024257366111080092 0.05892555620870993"/>
    <mass value="3.12474974677204"/>
    <inertia ixx="0.014842" ixy="-2.6e-05" ixz="-0.003268" iyy="0.016057" iyz="-0.000102" izz="0.003681"/>
  </inertial>
  <visual>
    <origin rpy="0 0 0" xyz="-0.0 -0.475 -0.4"/>
    <geometry>
      <mesh filename="package://mobile_manipulator_description/meshes/shoulder_left_1.stl" scale="0.001 0.001 0.001"/>
    </geometry>
    <material name="silver_default"/>
  </visual>
  <collision>
    <origin rpy="0 0 0" xyz="-0.0 -0.475 -0.4"/>
    <geometry>
      <mesh filename="package://mobile_manipulator_description/meshes/shoulder_left_1.stl" scale="0.001 0.001 0.001"/>
    </geometry>
  </collision>
</link>

<link name="wheel_bl_1">
  <inertial>
    <origin rpy="0 0 0" xyz="-2.0761170560490427e-14 0.0 1.9886869928598117e-14"/>
    <mass value="2.8760298995910287"/>
    <inertia ixx="0.009699" ixy="0.0" ixz="-0.0" iyy="0.014605" iyz="-0.0" izz="0.009699"/>
  </inertial>
  <visual>
    <origin rpy="0 0 0" xyz="0.35 -0.35 -0.1"/>
    <geometry>
      <mesh filename="package://mobile_manipulator_description/meshes/wheel_bl_1.stl" scale="0.001 0.001 0.001"/>
    </geometry>
    <material name="silver_default"/>
  </visual>
  <collision>
    <origin rpy="0 0 0" xyz="0.35 -0.35 -0.1"/>
    <geometry>
      <mesh filename="package://mobile_manipulator_description/meshes/wheel_bl_1.stl" scale="0.001 0.001 0.001"/>
    </geometry>
  </collision>
</link>

<link name="arm_right_1">
  <inertial>
    <origin rpy="0 0 0" xyz="0.19413326329620814 -0.012606374294724554 0.005895047633385331"/>
    <mass value="1.1196019663077494"/>
    <inertia ixx="0.00032" ixy="0.000436" ixz="0.000122" iyy="0.019542" iyz="-1.8e-05" izz="0.019409"/>
  </inertial>
  <visual>
    <origin rpy="0 0 0" xyz="-0.04388 0.515 -0.593021"/>
    <geometry>
      <mesh filename="package://mobile_manipulator_description/meshes/arm_right_1.stl" scale="0.001 0.001 0.001"/>
    </geometry>
    <material name="silver_default"/>
  </visual>
  <collision>
    <origin rpy="0 0 0" xyz="-0.04388 0.515 -0.593021"/>
    <geometry>
      <mesh filename="package://mobile_manipulator_description/meshes/arm_right_1.stl" scale="0.001 0.001 0.001"/>
    </geometry>
  </collision>
</link>

<link name="arm_left_1">
  <inertial>
    <origin rpy="0 0 0" xyz="0.19413326329620828 -0.012606374294733103 0.005895047633403427"/>
    <mass value="1.1196019663077494"/>
    <inertia ixx="0.00032" ixy="0.000436" ixz="0.000122" iyy="0.019542" iyz="-1.8e-05" izz="0.019409"/>
  </inertial>
  <visual>
    <origin rpy="0 0 0" xyz="-0.04388 -0.46 -0.593021"/>
    <geometry>
      <mesh filename="package://mobile_manipulator_description/meshes/arm_left_1.stl" scale="0.001 0.001 0.001"/>
    </geometry>
    <material name="silver_default"/>
  </visual>
  <collision>
    <origin rpy="0 0 0" xyz="-0.04388 -0.46 -0.593021"/>
    <geometry>
      <mesh filename="package://mobile_manipulator_description/meshes/arm_left_1.stl" scale="0.001 0.001 0.001"/>
    </geometry>
  </collision>
</link>

<link name="forearm_right_1">
  <inertial>
    <origin rpy="0 0 0" xyz="0.06010304679536271 0.0504534714766981 0.02502167030649416"/>
    <mass value="1.9557341461233821"/>
    <inertia ixx="0.001552" ixy="-0.000534" ixz="-0.000582" iyy="0.013654" iyz="-0.00025" izz="0.013657"/>
  </inertial>
  <visual>
    <origin rpy="0 0 0" xyz="-0.39388 0.515 -0.593021"/>
    <geometry>
      <mesh filename="package://mobile_manipulator_description/meshes/forearm_right_1.stl" scale="0.001 0.001 0.001"/>
    </geometry>
    <material name="silver_default"/>
  </visual>
  <collision>
    <origin rpy="0 0 0" xyz="-0.39388 0.515 -0.593021"/>
    <geometry>
      <mesh filename="package://mobile_manipulator_description/meshes/forearm_right_1.stl" scale="0.001 0.001 0.001"/>
    </geometry>
  </collision>
</link>

<link name="forearm_left_1">
  <inertial>
    <origin rpy="0 0 0" xyz="0.060103046795362824 0.05045347147668883 0.025021670306512256"/>
    <mass value="1.9557341461233821"/>
    <inertia ixx="0.001552" ixy="-0.000534" ixz="-0.000582" iyy="0.013654" iyz="-0.00025" izz="0.013657"/>
  </inertial>
  <visual>
    <origin rpy="0 0 0" xyz="-0.39388 -0.46 -0.593021"/>
    <geometry>
      <mesh filename="package://mobile_manipulator_description/meshes/forearm_left_1.stl" scale="0.001 0.001 0.001"/>
    </geometry>
    <material name="silver_default"/>
  </visual>
  <collision>
    <origin rpy="0 0 0" xyz="-0.39388 -0.46 -0.593021"/>
    <geometry>
      <mesh filename="package://mobile_manipulator_description/meshes/forearm_left_1.stl" scale="0.001 0.001 0.001"/>
    </geometry>
  </collision>
</link>

<link name="wrist_right_1">
  <inertial>
    <origin rpy="0 0 0" xyz="0.054203077066210414 2.7755575615628914e-16 3.7502179894843835e-07"/>
    <mass value="0.7930209099256357"/>
    <inertia ixx="0.000384" ixy="-0.0" ixz="-0.0" iyy="0.001295" iyz="-0.0" izz="0.001254"/>
  </inertial>
  <visual>
    <origin rpy="0 0 0" xyz="-0.61488 0.46 -0.623021"/>
    <geometry>
      <mesh filename="package://mobile_manipulator_description/meshes/wrist_right_1.stl" scale="0.001 0.001 0.001"/>
    </geometry>
    <material name="silver_default"/>
  </visual>
  <collision>
    <origin rpy="0 0 0" xyz="-0.61488 0.46 -0.623021"/>
    <geometry>
      <mesh filename="package://mobile_manipulator_description/meshes/wrist_right_1.stl" scale="0.001 0.001 0.001"/>
    </geometry>
  </collision>
</link>

<link name="wrist_left_1">
  <inertial>
    <origin rpy="0 0 0" xyz="0.054203077066210636 -9.103828801926284e-15 3.7502181804427437e-07"/>
    <mass value="0.7930209099256357"/>
    <inertia ixx="0.000384" ixy="-0.0" ixz="0.0" iyy="0.001295" iyz="0.0" izz="0.001254"/>
  </inertial>
  <visual>
    <origin rpy="0 0 0" xyz="-0.61488 -0.515 -0.623021"/>
    <geometry>
      <mesh filename="package://mobile_manipulator_description/meshes/wrist_left_1.stl" scale="0.001 0.001 0.001"/>
    </geometry>
    <material name="silver_default"/>
  </visual>
  <collision>
    <origin rpy="0 0 0" xyz="-0.61488 -0.515 -0.623021"/>
    <geometry>
      <mesh filename="package://mobile_manipulator_description/meshes/wrist_left_1.stl" scale="0.001 0.001 0.001"/>
    </geometry>
  </collision>
</link>

<link name="palm_right_1">
  <inertial>
    <origin rpy="0 0 0" xyz="0.04219292467141289 6.977751709769109e-14 3.7502179894843835e-07"/>
    <mass value="0.1617998720819448"/>
    <inertia ixx="3.8e-05" ixy="-0.0" ixz="-0.0" iyy="6.4e-05" iyz="0.0" izz="6.4e-05"/>
  </inertial>
  <visual>
    <origin rpy="0 0 0" xyz="-0.71988 0.46 -0.623021"/>
    <geometry>
      <mesh filename="package://mobile_manipulator_description/meshes/palm_right_1.stl" scale="0.001 0.001 0.001"/>
    </geometry>
    <material name="silver_default"/>
  </visual>
  <collision>
    <origin rpy="0 0 0" xyz="-0.71988 0.46 -0.623021"/>
    <geometry>
      <mesh filename="package://mobile_manipulator_description/meshes/palm_right_1.stl" scale="0.001 0.001 0.001"/>
    </geometry>
  </collision>
</link>

<link name="palm_left_1">
  <inertial>
    <origin rpy="0 0 0" xyz="0.042192924671413 6.039613253960852e-14 3.7502181715609595e-07"/>
    <mass value="0.1617998720819448"/>
    <inertia ixx="3.8e-05" ixy="-0.0" ixz="0.0" iyy="6.4e-05" iyz="0.0" izz="6.4e-05"/>
  </inertial>
  <visual>
    <origin rpy="0 0 0" xyz="-0.71988 -0.515 -0.623021"/>
    <geometry>
      <mesh filename="package://mobile_manipulator_description/meshes/palm_left_1.stl" scale="0.001 0.001 0.001"/>
    </geometry>
    <material name="silver_default"/>
  </visual>
  <collision>
    <origin rpy="0 0 0" xyz="-0.71988 -0.515 -0.623021"/>
    <geometry>
      <mesh filename="package://mobile_manipulator_description/meshes/palm_left_1.stl" scale="0.001 0.001 0.001"/>
    </geometry>
  </collision>
</link>

<link name="knuckle_right_1">
  <inertial>
    <origin rpy="0 0 0" xyz="0.014791665047523606 2.8555338740798852e-06 3.7502179894843835e-07"/>
    <mass value="0.49387627632174347"/>
    <inertia ixx="0.000186" ixy="-0.0" ixz="-0.0" iyy="0.000145" iyz="0.0" izz="0.000163"/>
  </inertial>
  <visual>
    <origin rpy="0 0 0" xyz="-0.78388 0.46 -0.623021"/>
    <geometry>
      <mesh filename="package://mobile_manipulator_description/meshes/knuckle_right_1.stl" scale="0.001 0.001 0.001"/>
    </geometry>
    <material name="silver_default"/>
  </visual>
  <collision>
    <origin rpy="0 0 0" xyz="-0.78388 0.46 -0.623021"/>
    <geometry>
      <mesh filename="package://mobile_manipulator_description/meshes/knuckle_right_1.stl" scale="0.001 0.001 0.001"/>
    </geometry>
  </collision>
</link>

<link name="knuckle_left_1">
  <inertial>
    <origin rpy="0 0 0" xyz="0.02516547946758041 1.3028412048865512e-05 3.7502181726711825e-07"/>
    <mass value="0.31471677202513093"/>
    <inertia ixx="0.000131" ixy="-0.0" ixz="0.0" iyy="0.000106" iyz="0.0" izz="0.000164"/>
  </inertial>
  <visual>
    <origin rpy="0 0 0" xyz="-0.78388 -0.515 -0.623021"/>
    <geometry>
      <mesh filename="package://mobile_manipulator_description/meshes/knuckle_left_1.stl" scale="0.001 0.001 0.001"/>
    </geometry>
    <material name="silver_default"/>
  </visual>
  <collision>
    <origin rpy="0 0 0" xyz="-0.78388 -0.515 -0.623021"/>
    <geometry>
      <mesh filename="package://mobile_manipulator_description/meshes/knuckle_left_1.stl" scale="0.001 0.001 0.001"/>
    </geometry>
  </collision>
</link>

<link name="finger_right_1_1">
  <inertial>
    <origin rpy="0 0 0" xyz="0.0667816014736462 0.003796343581673578 -7.734064779374439e-05"/>
    <mass value="0.058672001092002074"/>
    <inertia ixx="4e-06" ixy="-6e-06" ixz="0.0" iyy="0.000102" iyz="0.0" izz="0.000105"/>
  </inertial>
  <visual>
    <origin rpy="0 0 0" xyz="-0.81888 0.49 -0.623021"/>
    <geometry>
      <mesh filename="package://mobile_manipulator_description/meshes/finger_right_1_1.stl" scale="0.001 0.001 0.001"/>
    </geometry>
    <material name="silver_default"/>
  </visual>
  <collision>
    <origin rpy="0 0 0" xyz="-0.81888 0.49 -0.623021"/>
    <geometry>
      <mesh filename="package://mobile_manipulator_description/meshes/finger_right_1_1.stl" scale="0.001 0.001 0.001"/>
    </geometry>
  </collision>
</link>

<link name="finger_right_2_1">
  <inertial>
    <origin rpy="0 0 0" xyz="0.0667816014736462 -0.0037963435816733004 7.809069139164126e-05"/>
    <mass value="0.058672001092002074"/>
    <inertia ixx="4e-06" ixy="6e-06" ixz="-0.0" iyy="0.000102" iyz="0.0" izz="0.000105"/>
  </inertial>
  <visual>
    <origin rpy="0 0 0" xyz="-0.81888 0.43 -0.623021"/>
    <geometry>
      <mesh filename="package://mobile_manipulator_description/meshes/finger_right_2_1.stl" scale="0.001 0.001 0.001"/>
    </geometry>
    <material name="silver_default"/>
  </visual>
  <collision>
    <origin rpy="0 0 0" xyz="-0.81888 0.43 -0.623021"/>
    <geometry>
      <mesh filename="package://mobile_manipulator_description/meshes/finger_right_2_1.stl" scale="0.001 0.001 0.001"/>
    </geometry>
  </collision>
</link>

<link name="finger_left_1_1">
  <inertial>
    <origin rpy="0 0 0" xyz="0.06678160147364653 -0.003796343581682571 7.80906914097379e-05"/>
    <mass value="0.058672001092002074"/>
    <inertia ixx="4e-06" ixy="6e-06" ixz="-0.0" iyy="0.000102" iyz="0.0" izz="0.000105"/>
  </inertial>
  <visual>
    <origin rpy="0 0 0" xyz="-0.81888 -0.545 -0.623021"/>
    <geometry>
      <mesh filename="package://mobile_manipulator_description/meshes/finger_left_1_1.stl" scale="0.001 0.001 0.001"/>
    </geometry>
    <material name="silver_default"/>
  </visual>
  <collision>
    <origin rpy="0 0 0" xyz="-0.81888 -0.545 -0.623021"/>
    <geometry>
      <mesh filename="package://mobile_manipulator_description/meshes/finger_left_1_1.stl" scale="0.001 0.001 0.001"/>
    </geometry>
  </collision>
</link>

<link name="finger_left_2_1">
  <inertial>
    <origin rpy="0 0 0" xyz="0.06678160147364653 0.003796343581664363 -7.734064777542571e-05"/>
    <mass value="0.058672001092002074"/>
    <inertia ixx="4e-06" ixy="-6e-06" ixz="0.0" iyy="0.000102" iyz="0.0" izz="0.000105"/>
  </inertial>
  <visual>
    <origin rpy="0 0 0" xyz="-0.81888 -0.485 -0.623021"/>
    <geometry>
      <mesh filename="package://mobile_manipulator_description/meshes/finger_left_2_1.stl" scale="0.001 0.001 0.001"/>
    </geometry>
    <material name="silver_default"/>
  </visual>
  <collision>
    <origin rpy="0 0 0" xyz="-0.81888 -0.485 -0.623021"/>
    <geometry>
      <mesh filename="package://mobile_manipulator_description/meshes/finger_left_2_1.stl" scale="0.001 0.001 0.001"/>
    </geometry>
  </collision>
</link>

<joint name="dummy_joint" type="fixed">
  <parent link="dummy"/>
  <child link="base_link"/>
</joint>

<joint name="motor_fl" type="continuous">
  <origin rpy="0 0 0" xyz="0.35 0.35 0.1"/>
  <parent link="base_link"/>
  <child link="wheel_fl_1"/>
  <axis xyz="0.0 1.0 -0.0"/>
</joint>

<joint name="motor_fr" type="continuous">
  <origin rpy="0 0 0" xyz="0.35 -0.35 0.1"/>
  <parent link="base_link"/>
  <child link="wheel_fr_1"/>
  <axis xyz="0.0 1.0 -0.0"/>
</joint>

<joint name="motor_br" type="continuous">
  <origin rpy="0 0 0" xyz="-0.35 -0.35 0.1"/>
  <parent link="base_link"/>
  <child link="wheel_br_1"/>
  <axis xyz="0.0 1.0 -0.0"/>
</joint>

<joint name="lidar_joint" type="fixed">
  <origin rpy="0 0 0" xyz="0.0 0.0 0.675"/>
  <parent link="base_link"/>
  <child link="lidar_1"/>
</joint>

<joint name="arm_base_right_joint" type="fixed">
  <origin rpy="0 0 0" xyz="0.0 -0.5 0.35"/>
  <parent link="base_link"/>
  <child link="arm_base_right_1"/>
</joint>

<joint name="arm_base_left_joint" type="fixed">
  <origin rpy="0 0 0" xyz="0.0 0.475 0.35"/>
  <parent link="base_link"/>
  <child link="arm_base_left_1"/>
</joint>

<joint name="shoulder_right_joint" type="continuous">
  <origin rpy="0 0 0" xyz="0.0 0.0 0.05"/>
  <parent link="arm_base_right_1"/>
  <child link="shoulder_right_1"/>
  <axis xyz="0.0 0.0 1.0"/>
</joint>

<joint name="shoulder_left_joint" type="continuous">
  <origin rpy="0 0 0" xyz="0.0 0.0 0.05"/>
  <parent link="arm_base_left_1"/>
  <child link="shoulder_left_1"/>
  <axis xyz="0.0 -0.0 1.0"/>
</joint>

<joint name="motor_bl" type="continuous">
  <origin rpy="0 0 0" xyz="-0.35 0.35 0.1"/>
  <parent link="base_link"/>
  <child link="wheel_bl_1"/>
  <axis xyz="0.0 1.0 -0.0"/>
</joint>

<joint name="arm_right_joint" type="continuous">
  <origin rpy="0 0 0" xyz="0.04388 -0.015 0.193021"/>
  <parent link="shoulder_right_1"/>
  <child link="arm_right_1"/>
  <axis xyz="0.0 -1.0 0.0"/>
</joint>

<joint name="arm_left_joint" type="continuous">
  <origin rpy="0 0 0" xyz="0.04388 -0.015 0.193021"/>
  <parent link="shoulder_left_1"/>
  <child link="arm_left_1"/>
  <axis xyz="0.0 -1.0 -0.0"/>
</joint>

<joint name="forearm_right_joint" type="continuous">
  <origin rpy="0 0 0" xyz="0.35 0.0 0.0"/>
  <parent link="arm_right_1"/>
  <child link="forearm_right_1"/>
  <axis xyz="0.0 1.0 0.0"/>
</joint>

<joint name="forearm_left_joint" type="continuous">
  <origin rpy="0 0 0" xyz="0.35 0.0 0.0"/>
  <parent link="arm_left_1"/>
  <child link="forearm_left_1"/>
  <axis xyz="0.0 -1.0 -0.0"/>
</joint>

<joint name="wrist_right_joint" type="continuous">
  <origin rpy="0 0 0" xyz="0.221 0.055 0.03"/>
  <parent link="forearm_right_1"/>
  <child link="wrist_right_1"/>
  <axis xyz="-1.0 0.0 0.0"/>
</joint>

<joint name="wrist_left_joint" type="continuous">
  <origin rpy="0 0 0" xyz="0.221 0.055 0.03"/>
  <parent link="forearm_left_1"/>
  <child link="wrist_left_1"/>
  <axis xyz="-1.0 0.0 0.0"/>
</joint>

<joint name="palm_right_joint" type="continuous">
  <origin rpy="0 0 0" xyz="0.105 0.0 0.0"/>
  <parent link="wrist_right_1"/>
  <child link="palm_right_1"/>
  <axis xyz="0.0 -1.0 0.0"/>
</joint>

<joint name="palm_left_joint" type="continuous">
  <origin rpy="0 0 0" xyz="0.105 0.0 0.0"/>
  <parent link="wrist_left_1"/>
  <child link="palm_left_1"/>
  <axis xyz="0.0 1.0 0.0"/>
</joint>

<joint name="knuckle_right_joint" type="continuous">
  <origin rpy="0 0 0" xyz="0.064 0.0 0.0"/>
  <parent link="palm_right_1"/>
  <child link="knuckle_right_1"/>
  <axis xyz="1.0 0.0 0.0"/>
</joint>

<joint name="knuckle_left_joint" type="continuous">
  <origin rpy="0 0 0" xyz="0.064 0.0 0.0"/>
  <parent link="palm_left_1"/>
  <child link="knuckle_left_1"/>
  <axis xyz="-1.0 0.0 0.0"/>
</joint>

<joint name="finger_right_1_joint" type="continuous">
  <origin rpy="0 0 0" xyz="0.035 -0.03 0.0"/>
  <parent link="knuckle_right_1"/>
  <child link="finger_right_1_1"/>
  <axis xyz="0.0 0.0 1.0"/>
</joint>

<joint name="finger_right_2_joint" type="continuous">
  <origin rpy="0 0 0" xyz="0.035 0.03 0.0"/>
  <parent link="knuckle_right_1"/>
  <child link="finger_right_2_1"/>
  <axis xyz="0.0 0.0 1.0"/>
</joint>

<joint name="finger_left_1_joint" type="continuous">
  <origin rpy="0 0 0" xyz="0.035 0.03 0.0"/>
  <parent link="knuckle_left_1"/>
  <child link="finger_left_1_1"/>
  <axis xyz="0.0 -0.0 1.0"/>
</joint>

<joint name="finger_left_2_joint" type="continuous">
  <origin rpy="0 0 0" xyz="0.035 -0.03 0.0"/>
  <parent link="knuckle_left_1"/>
  <child link="finger_left_2_1"/>
  <axis xyz="0.0 0.0 -1.0"/>
</joint>

</robot>
